<?xml version="1.0"?>

<robot name="robot_differential" xmlns:xacro="http://www.ros.org/wiki/xacro" >
    <!--Inertial Function-->
    <xacro:include filename="inertial.xacro"/>

    <xacro:property name="chassis_length" value="0.335"/>
    <xacro:property name="chassis_width" value="0.265"/>
    <xacro:property name="chassis_height" value="0.138"/>
    <xacro:property name="chassis_mass" value="1.0"/>
    <xacro:property name="wheel_radius" value="0.033"/>
    <xacro:property name="wheel_thickness" value="0.026"/>
    <xacro:property name="wheel_mass" value="0.05"/>
    <xacro:property name="wheel_offset_x" value="0.226"/>
    <xacro:property name="wheel_offset_y" value="0.1485"/>
    <xacro:property name="wheel_offset_z" value="0.01"/>
    <xacro:property name="caster_wheel_radius" value="0.01"/>
    <xacro:property name="caster_wheel_mass" value="0.01"/>
    <xacro:property name="caster_wheel_offset_x" value="0.075"/>
    <xacro:property name="caster_wheel_offset_z" value="${wheel_offset_z - wheel_radius + caster_wheel_radius}"/>

    <material name="white">
        <color rgba="1 1 1 1" />
    </material>

    <material name="brown">
        <color rgba="0.8706 0.8118 0.7647 1.0"/>
    </material>

    <material name="blue">
        <color rgba="0.2 0.2 1 1"/>
    </material>

    <material name="black">
        <color rgba="0 0 0 1"/>
    </material>

    <material name="red">
        <color rgba="1 0 0 1"/>
    </material>

    <!--Base Link-->
    <link name="base_link">

    </link>

    <!--Base Footprint link-->

    <joint name="base_footprint_joint" type="fixed">
        <parent link="base_link"/>
        <child link="base_footprint"/>
        <origin xyz="0 0 0" rpy="0 0 0"/>
    </joint>

    <link name="base_footprint">
    </link>

    <!--Chasis Link-->

    <joint name="chassis_joint" type="fixed">
        <parent link="base_link"/>
        <child link="chassis"/>
        <origin xyz="${-wheel_offset_x} 0 ${-wheel_offset_z}"/>
    </joint>

    <link name="chassis">
        <visual>
            <origin xyz="${chassis_length/2} 0 ${chassis_height/2}"/>
            <geometry>
                <box size="${chassis_length} ${chassis_width} ${chassis_height}"/>
            </geometry>
            <material name="brown"/>
        </visual>
        <collision>
            <origin xyz="${chassis_length/2} 0 ${chassis_height/2}"/>
            <geometry>
                <box size="${chassis_length} ${chassis_width} ${chassis_height}"/>
            </geometry>
        </collision>
        <xacro:inertial_box mass="0.5" x="${chassis_length}" y="${chassis_width}" z="${chassis_height}">
            <origin xyz="${chassis_length/2} 0 ${chassis_height/2}" rpy="0 0 0"/>
        </xacro:inertial_box>
    </link>

    <gazebo reference="chassis">
        <material>Gazebo/Brown</material>
    </gazebo>

    <!--Left wheel link-->

    <joint name="left_wheel_joint" type="continuous">
        <parent link="base_link"/>
        <child link="left_wheel"/>
        <origin xyz="0 ${wheel_offset_y} 0" rpy="-${pi/2} 0 0" />
        <axis xyz="0 0 1"/>
    </joint>

    <link name="left_wheel">
        <visual>
            <geometry>
                <cylinder radius="${wheel_radius}" length="${wheel_thickness}"/>
            </geometry>
            <material name="blue"/>
        </visual>
        <collision>
            <geometry>
                <sphere radius="${wheel_radius}"/>
            </geometry>
        </collision>
        <xacro:inertial_cylinder mass="${wheel_mass}" length="${wheel_thickness}" radius="${wheel_radius}">
            <origin xyz="0 0 0" rpy="0 0 0"/>
        </xacro:inertial_cylinder>
    </link>

    <gazebo reference="left_wheel">
        <material>Gazebo/Blue</material>
    </gazebo>

    <!--Right wheel link-->

    <joint name="right_wheel_joint" type="continuous">
        <parent link="base_link"/>
        <child link="right_wheel"/>
        <origin xyz="0 ${-wheel_offset_y} 0" rpy="${pi/2} 0 0" />
        <axis xyz="0 0 -1"/>
    </joint>

    <link name="right_wheel">
        <visual>
            <geometry>
                <cylinder radius="${wheel_radius}" length="${wheel_thickness}"/>
            </geometry>
            <material name="blue"/>
        </visual>
        <collision>
            <geometry>
                <sphere radius="${wheel_radius}"/>
            </geometry>
        </collision>
        <xacro:inertial_cylinder mass="${wheel_mass}" length="${wheel_thickness}" radius="${wheel_radius}">
            <origin xyz="0 0 0" rpy="0 0 0"/>
        </xacro:inertial_cylinder>
    </link>

    <gazebo reference="right_wheel">
        <material>Gazebo/Blue</material>
    </gazebo>

    <!--Caster wheel link-->

    <joint name="caster_wheel_joint" type="fixed">
        <parent link="chassis"/>
        <child link="caster_wheel"/>
        <origin xyz="${caster_wheel_offset_x} 0 ${caster_wheel_offset_z}"/>
    </joint>


    <link name="caster_wheel">
        <visual>
            <geometry>
                <sphere radius="${caster_wheel_radius}"/>
            </geometry>
            <material name="white"/>
        </visual>
        <collision>
            <geometry>
                <sphere radius="${caster_wheel_radius}"/>
            </geometry>
        </collision>
        <xacro:inertial_sphere mass="${caster_wheel_mass}" radius="${caster_wheel_radius}">
            <origin xyz="0 0 0" rpy="0 0 0"/>
        </xacro:inertial_sphere>
    </link>

    <gazebo reference="caster_wheel">
        <material>Gazebo/White</material>
        <mu1 value="0.001"/>
        <mu2 value="0.001"/>
    </gazebo>

    <!-- GAZEBO Control-->
    <gazebo>
        <plugin name="diff_drive" filename="libgazebo_ros_diff_drive.so">


            <left_joint>left_wheel_joint</left_joint>
            <right_joint>right_wheel_joint</right_joint>
        
            <wheel_separation>0.297</wheel_separation>
            <wheel_diameter>0.066</wheel_diameter>



            <max_wheel_torque>200</max_wheel_torque>
            <max_wheel_acceleration>10</max_wheel_acceleration>

            
            <!-- Output -->
            <odometry_frame>odom</odometry_frame>
            <robot_base_frame>base_link</robot_base_frame>

            <publish_odom>true</publish_odom>
            <publish_odom_tf>true</publish_odom_tf>
            <publish_wheel_tf>true</publish_wheel_tf>

        </plugin>
    </gazebo> 

    <!--Lidar-->

     <joint name="laser_joint" type="fixed">
        <parent link="chassis"/>
        <child link="laser_frame"/>
        <origin xyz="0.122 0 0.212" rpy="0 0 0"/>
    </joint>

    <link name="laser_frame">
        <visual>
            <geometry>
                <cylinder radius="0.05" length="0.04"/>
            </geometry>
            <material name="black"/>
        </visual>
        <visual>
            <origin xyz="0 0 -0.05"/>
            <geometry>
                <cylinder radius="0.01" length="0.1"/>
            </geometry>
            <material name="black"/>
        </visual>
        <collision>
            <geometry>
                <cylinder radius="0.05" length="0.04"/>
            </geometry>
        </collision>
        <xacro:inertial_cylinder mass="0.1" length="0.04" radius="0.05">
            <origin xyz="0 0 0" rpy="0 0 0"/>
        </xacro:inertial_cylinder>
    </link>

    <!--Lidar Gazebo-->
    <gazebo reference="laser_frame">
        <material>Gazebo/Black</material>

        <sensor name="laser" type="ray">
            <pose> 0 0 0 0 0 0 </pose>
            <visualize>true</visualize>
            <update_rate>10</update_rate>
            <ray>
                <scan>
                    <horizontal>
                        <samples>360</samples>
                        <min_angle>-3.14</min_angle>
                        <max_angle>3.14</max_angle>
                    </horizontal>
                </scan>
                <range>
                    <min>0.3</min>
                    <max>12</max>
                </range>
            </ray>
            <plugin name="laser_controller" filename="libgazebo_ros_ray_sensor.so">
                <ros>
                    <argument>~/out:=scan</argument>
                </ros>
                <!--OUTPUT Scan-->
                <output_type>sensor_msgs/LaserScan</output_type>
                <frame_name>laser_frame</frame_name>
            </plugin>
        </sensor>
    </gazebo>

    <!--Depth Camera-->
     <joint name="camera_joint" type="fixed">
        <parent link="chassis"/>
        <child link="camera_link"/>
        <origin xyz="0.34 0 0.15" rpy="0 0 0"/>
    </joint>

    <link name="camera_link">
        <visual>
            <geometry>
                <box size="0.021 0.10 0.05"/>
            </geometry>
            <material name="red"/>
        </visual>
    </link>


    <joint name="camera_optical_joint" type="fixed">
        <parent link="camera_link"/>
        <child link="camera_link_optical"/>
        <origin xyz="0 0 0" rpy="${-pi/2} 0 ${-pi/2}"/>
    </joint>

    <link name="camera_link_optical"></link>


    <!--Depth Camera in Gazebo-->
    <gazebo reference="camera_link">
        <material>Gazebo/Red</material>

        <sensor name="camera" type="depth">
            <pose> 0 0 0 0 0 0 </pose>
            <visualize>true</visualize>
            <update_rate>20</update_rate>
            <camera>
                <horizontal_fov>1.70</horizontal_fov>
                <image>
                    <format>B8G8R8</format>
                    <width>640</width>
                    <height>480</height>
                </image>
                <clip>
                    <near>0.012</near>
                    <far>8.0</far>
                </clip>
            </camera>
            <plugin name="camera_controller" filename="libgazebo_ros_camera.so">
                <frame_name>camera_link_optical</frame_name>
                <min_depth>0.05</min_depth>
                <max_depth>100.0</max_depth>
            </plugin>
        </sensor>
    </gazebo>

</robot>